Workbook
Name A_r_b_e_i_t_s_______P_l_a_n_u_n_g: #REF!

Sheet Terminplan
F1: Tag 1 | J1: Tag 2 | N1: Tag 3 | R1: Tag 4 | V1: Tag 5 | Z1: Tag 6 | AD1: Tag 7 | AH1: Tag 8
F2: 46084 | J2: 46086 | N2: 46091 | R2: 46093 | V2: 46098 | Z2: 46100 | AD2: 46105 | AH2: 46107
C3: Tages - SOLL | F3: =SUM(F8:I8,F10:I10,F12:I12,F14:I14,F16:I16,F20:I20,F22:I22,F24:I24,F26:I26,F28:I28,F32:I32,F34:I34,F36:I36,F38:I38,F42:I42,F46:I46,F48:I48,F50:I50,F54:I54,F56:I56,F60:I60,F64:I64,F44:I44)/4 -> 3.875 | J3: =SUM(J8:M8,J10:M10,J12:M12,J14:M14,J16:M16,J26:M26,J28:M28,J32:M32,J34:M34,J36:M36,J38:M38,J42:M42,J46:M46,J48:M48,J50:M50,J54:M54,J56:M56,J60:M60,J64:M64,J24:L24,J22:K22,J20,J44:M44)/4 -> 3.375 | N3: =SUM(N8:Q8,N10:Q10,N12:Q12,N14:Q14,N16:Q16,N20:Q20,N22:Q22,N24:Q24,N26:Q26,N28:Q28,N32,N34:O34,N36:O36,N38:Q38,N42:Q42,N46:Q46,N48:Q48,N50:Q50,N54:Q54,N56:Q56,N60:Q60,N64:Q64,N44:Q44)/4 -> 3.3125 | R3: =SUM(R8:U8,R10:U10,R12:U12,R14:U14,R16:U16,R26:U26,R28:U28,R32:U32,R34:U34,R36:U36,R38:U38,R42:U42,R46:U46,R48:U48,R50:U50,R54:U54,R56:U56,R60:U60,R64:U64,R24:U24,R22:U22,R20:U20,R44:U44)/4 -> 2.1875 | V3: =SUM(V8:Y8,V10:Y10,V12:Y12,V14:Y14,V16:Y16,V20:Y20,V22:Y22,V24:Y24,V26:Y26,V28:Y28,V32:Y32,V34:Y34,V36:Y36,V38:Y38,V42:Y42,V46:Y46,V48:Y48,V50:Y50,V54:Y54,V56:Y56,V60:Y60,V64:Y64,V44:Y44)/4 -> 0.5875 | Z3: =SUM(Z8:AC8,Z10:AC10,Z12:AC12,Z14:AC14,Z16:AC16,Z20:AC20,Z22:AC22,Z24:AC24,Z26:AC26,Z28:AC28,Z32:AC32,Z34:AC34,Z36:AC36,Z38:AC38,Z42:AC42,Z46:AC46,Z48:AC48,Z50:AC50,Z54:AC54,Z56:AC56,Z60:AC60,Z64:AC64,Z44:AC44)/4 -> 0.4375 | AD3: =SUM(AD8:AG8,AD10:AG10,AD12:AG12,AD14:AG14,AD16:AG16,AD20:AG20,AD22:AG22,AD24:AG24,AD26:AG26,AD28:AG28,AD32:AG32,AD34:AG34,AD36:AG36,AD38:AG38,AD42:AG42,AD46:AG46,AD48:AG48,AD50:AG50,AD54:AG54,AD56:AG56,AD60:AG60,AD64:AG64) -> 0 | AH3: =SUM(AH8:AK8,AH10:AK10,AH12:AK12,AH14:AK14,AH16:AK16,AH20:AK20,AH22:AK22,AH24:AK24,AH26:AK26,AH28:AK28,AH32:AK32,AH34:AK34,AH36:AK36,AH38:AK38,AH42:AK42,AH46:AK46,AH48:AK48,AH50:AK50,AH54:AK54,AH56:AK56,AH60:AK60,AH64:AK64) -> 0
C4: Tages - IST | F4: =SUM(F9:I9,F11:I11,F13:I13,F15:I15,F17:I17,F21:I21,F23:I23,F25:I25,F27:I27,F29:I29,F33:I33,F35:I35,F37:I37,F39:I39,F43:I43,F47:I47,F49:I49,F51:I51,F55:I55,F57:I57,F61:I61,F65:I65,F45:I45)/4 -> 4.25 | J4: =SUM(J9:M9,J11:M11,J13:M13,J15:M15,J17:M17,J27:M27,J29:M29,J33:M33,J35:M35,J37:M37,J39:M39,J43:M43,J47:M47,J49:M49,J51:M51,J55:M55,J57:M57,J61:M61,J65:M65,J21,J23:K23,J25:L25,J45:M45)/4 -> 4.125 | N4: =SUM(N9:Q9,N11:Q11,N13:Q13,N15:Q15,N17:Q17,N21:Q21,N23:Q23,N25:Q25,N27:Q27,N29:Q29,N33:Q33,N35:Q35,N37:Q37,N39:Q39,N43:Q43,N47:Q47,N49:Q49,N51:Q51,N55:Q55,N57:Q57,N61:Q61,N65:Q65,N45:Q45) -> 0.5 | R4: =SUM(R9:U9,R11:U11,R13:U13,R15:U15,R17:U17,J21:M21,J23:M23,J25:M25,R27:U27,R29:U29,R33:U33,R35:U35,R37:U37,R39:U39,R43:U43,R47:U47,R49:U49,R51:U51,R55:U55,R57:U57,R61:U61,R65:U65,R19:U19,R21:U21,R23:U23,R25:U25,R45:U45) -> 24 | V4: =SUM(V9:Y9,V11:Y11,V13:Y13,V15:Y15,V17:Y17,V21:Y21,V23:Y23,V25:Y25,V27:Y27,V29:Y29,V33:Y33,V35:Y35,V37:Y37,V39:Y39,V43:Y43,V47:Y47,V49:Y49,V51:Y51,V55:Y55,V57:Y57,V61:Y61,V65:Y65,V45:Y45) -> 0 | Z4: =SUM(Z9:AC9,Z11:AC11,Z13:AC13,Z15:AC15,Z17:AC17,Z21:AC21,Z23:AC23,Z25:AC25,Z27:AC27,Z29:AC29,Z33:AC33,Z35:AC35,Z37:AC37,Z39:AC39,Z43:AC43,Z47:AC47,Z49:AC49,Z51:AC51,Z55:AC55,Z57:AC57,Z61:AC61,Z65:AC65,Z45:AC45) -> 0 | AD4: =SUM(AD9:AG9,AD11:AG11,AD13:AG13,AD15:AG15,AD17:AG17,AD21:AG21,AD23:AG23,AD25:AG25,AD27:AG27,AD29:AG29,AD33:AG33,AD35:AG35,AD37:AG37,AD39:AG39,AD43:AG43,AD47:AG47,AD49:AG49,AD51:AG51,AD55:AG55,AD57:AG57,AD61:AG61,AD65:AG65) -> 0 | AH4: =SUM(AH9:AK9,AH11:AK11,AH13:AK13,AH15:AK15,AH17:AK17,AH21:AK21,AH23:AK23,AH25:AK25,AH27:AK27,AH29:AK29,AH33:AK33,AH35:AK35,AH37:AK37,AH39:AK39,AH43:AK43,AH47:AK47,AH49:AK49,AH51:AK51,AH55:AK55,AH57:AK57,AH61:AK61,AH65:AK65) -> 0
C5: Projektphasen - Projektschritte | D5: Stunden | F5: =4/(F3-F4) -> -10.666667 | J5: =J3-J4 -> -0.75 | N5: =N3-N4 -> 2.8125 | R5: =R3-R4 -> -21.8125 | V5: =V3-V4 -> 0.5875 | Z5: =Z3-Z4 -> 0.4375 | AD5: =AD3-AD4 -> 0 | AH5: =AH3-AH4 -> 0
D6: Soll | E6: IST
C7: Initialisierung
C8: PIA | D8: =SUM(F8:AG8) -> 2.6 | F8: =SUM('Ch.G'!D4,St.G!D4,Be.P!D4,Su.S!D4) -> 2.6
E9: =SUM(F9:AG9) -> 3 | F9: =SUM('Ch.G'!E4,St.G!E4,Be.P!E4,Su.S!E4) -> 3
C10: Stakholderliste | D10: =SUM(F10:AG10) -> 2.6 | G10: =SUM('Ch.G'!D5,St.G!D5,Be.P!D5,Su.S!D5) -> 2.6
E11: =SUM(F11:AG11) -> 7 | G11: =SUM('Ch.G'!E5,St.G!E5,Be.P!E5,Su.S!E5) -> 7
C12: Risikoliste vorhanden | D12: =SUM(F12:AG12) -> 2.6 | H12: =SUM('Ch.G'!D6,St.G!D6,Be.P!D6,Su.S!D6) -> 2.6
E13: =SUM(F13:AG13) -> 2 | H13: =SUM('Ch.G'!E6,St.G!E6,Be.P!E6,Su.S!E6) -> 2
C14: Repo eingereicht | D14: =SUM(F14:AG14) -> 2.6 | H14: =SUM('Ch.G'!D7,St.G!D7,Be.P!D7,Su.S!D7) -> 2.6
E15: =SUM(F15:AG15) -> 3 | H15: =SUM('Ch.G'!E7,St.G!E7,Be.P!E7,Su.S!E7) -> 3
C16: Freigabe durch Auftraggeber | D16: =SUM(F16:AG16) -> 2.6 | I16: =SUM('Ch.G'!D8,St.G!D8,Be.P!D8,Su.S!D8) -> 2.6
E17: =SUM(F17:AG17) -> 1.5 | I17: =SUM('Ch.G'!E8,St.G!E8,Be.P!E8,Su.S!E8) -> 1.5
C19: Konzept
C20: PMP | D20: =SUM(F20:AG20) -> 5.2 | J20: =SUM('Ch.G'!D10,St.G!D10,Be.P!D10,Su.S!D10) -> 2.6 | K20: =SUM('Ch.G'!D10,St.G!D10,Be.P!D10,Su.S!D10) -> 2.6
E21: =SUM(F21:AG21) -> 6 | J21: =SUM('Ch.G'!E10,St.G!E10,Be.P!E10,Su.S!E10) -> 3 | K21: =SUM('Ch.G'!E10,St.G!E10,Be.P!E10,Su.S!E10) -> 3
C22: GDD/Lösungskonzept | D22: =SUM(F22:AG22) -> 5.2 | K22: =SUM('Ch.G'!D11,St.G!D11,Be.P!D11,Su.S!D11) -> 2.6 | L22: =SUM('Ch.G'!D11,St.G!D11,Be.P!D11,Su.S!D11) -> 2.6
E23: =SUM(F23:AG23) -> 4 | K23: =SUM('Ch.G'!E11,St.G!E11,Be.P!E11,Su.S!E11) -> 2 | L23: =SUM('Ch.G'!E11,St.G!E11,Be.P!E11,Su.S!E11) -> 2
C24: Teststrategie vorhanden | D24: =SUM(F24:AG24) -> 5.2 | L24: =SUM('Ch.G'!D12,St.G!D12,Be.P!D12,Su.S!D12) -> 2.6 | M24: =SUM('Ch.G'!D12,St.G!D12,Be.P!D12,Su.S!D12) -> 2.6
E25: =SUM(F25:AG25) -> 6 | L25: =SUM('Ch.G'!E12,St.G!E12,Be.P!E12,Su.S!E12) -> 3 | M25: =SUM('Ch.G'!E12,St.G!E12,Be.P!E12,Su.S!E12) -> 3
C26: Freigabe für Umsetzung | D26: =SUM(F26:AG26) -> 2.6 | M26: =SUM('Ch.G'!D13,St.G!D13,Be.P!D13,Su.S!D13) -> 2.6
E27: =SUM(F27:AG27) -> 4 | M27: =SUM('Ch.G'!E13,St.G!E13,Be.P!E13,Su.S!E13) -> 4
C28: Präsention beim Auftraggeber | D28: =SUM(F28:AG28) -> 2.6 | M28: =SUM('Ch.G'!D14,St.G!D14,Be.P!D14,Su.S!D14) -> 2.6
E29: =SUM(F29:AG29) -> 4 | M29: =SUM('Ch.G'!E14,St.G!E14,Be.P!E14,Su.S!E14) -> 4
C31: Realisierung
C32: lauffähige Zwischenstand | D32: =SUM(F32:AG32) -> 8 | N32: =SUM('Ch.G'!D16,St.G!D16,Be.P!D16,Su.S!D16) -> 4 | O32: =SUM('Ch.G'!D16,St.G!D16,Be.P!D16,Su.S!D16) -> 4
E33: =SUM(F33:AG33) -> 0 | N33: =SUM('Ch.G'!E16,St.G!E16,Be.P!E16,Su.S!E16) -> 0 | O33: =SUM('Ch.G'!E16,St.G!E16,Be.P!E16,Su.S!E16) -> 0
C34: Testprotokolle | D34: =SUM(F34:AG34) -> 12 | O34: =SUM('Ch.G'!D17,St.G!D17,Be.P!D17,Su.S!D17) -> 4 | P34: =SUM('Ch.G'!D17,St.G!D17,Be.P!D17,Su.S!D17) -> 4 | Q34: =SUM('Ch.G'!D17,St.G!D17,Be.P!D17,Su.S!D17) -> 4
E35: =SUM(F35:AG35) -> 0 | O35: =SUM('Ch.G'!E17,St.G!E17,Be.P!E17,Su.S!E17) -> 0 | P35: =SUM('Ch.G'!E17,St.G!E17,Be.P!E17,Su.S!E17) -> 0 | Q35: =SUM('Ch.G'!E17,St.G!E17,Be.P!E17,Su.S!E17) -> 0
C36: Statusbericht | D36: =SUM(F36:AG36) -> 20 | O36: =SUM('Ch.G'!D18,St.G!D18,Be.P!D18,Su.S!D18) -> 4 | P36: =SUM('Ch.G'!D18,St.G!D18,Be.P!D18,Su.S!D18) -> 4 | Q36: =SUM('Ch.G'!D18,St.G!D18,Be.P!D18,Su.S!D18) -> 4 | R36: =SUM('Ch.G'!D18,St.G!D18,Be.P!D18,Su.S!D18) -> 4 | S36: =SUM('Ch.G'!D18,St.G!D18,Be.P!D18,Su.S!D18) -> 4
E37: =SUM(F37:AG37) -> 0 | O37: =SUM('Ch.G'!E18,St.G!E18,Be.P!E18,Su.S!E18) -> 0 | P37: =SUM('Ch.G'!E18,St.G!E18,Be.P!E18,Su.S!E18) -> 0 | Q37: =SUM('Ch.G'!E18,St.G!E18,Be.P!E18,Su.S!E18) -> 0 | R37: =SUM('Ch.G'!E18,St.G!E18,Be.P!E18,Su.S!E18) -> 0 | S37: =SUM('Ch.G'!E18,St.G!E18,Be.P!E18,Su.S!E18) -> 0
C38: Offene Risitken/Changes transparent Dokumentieren | D38: =SUM(F38:AG38) -> 0 | T38: =SUM('Ch.G'!E19,St.G!E19,Be.P!E19,Su.S!E19) -> 0 | U38: =SUM('Ch.G'!E19,St.G!E19,Be.P!E19,Su.S!E19) -> 0
E39: =SUM(F39:AG39) -> 8 | T39: =SUM('Ch.G'!D19,St.G!D19,Be.P!D19,Su.S!D19) -> 4 | U39: =SUM('Ch.G'!D19,St.G!D19,Be.P!D19,Su.S!D19) -> 4
C41: Einführung
C42: Abnahmeprotokoll | D42: =SUM(F42:AG42) -> 0.4 | V42: 0.4
E43: =SUM(F43:AG43) -> 0
...

Sheet Ch.G
B2: Tätigkeit | C2: Datum | D2: SOLL Stunden | E2: IST Stunden
B3: Initialisierung
B4: PIA | C4: 46056 | D4: 0.65 | E4: 1
B5: Stakholderliste | C5: 46056 | D5: 0.65 | E5: 1
B6: Risikoliste vorhanden | C6: 46056 | D6: 0.65 | E6: 1
B7: Repo eingereicht | C7: 46056 | D7: 0.65 | E7: 1
B8: Freigabe durch Auftraggeber | C8: 46056 | D8: 0.65 | E8: 0.5
B9: Konzept
B10: PMP | C10: 46063 | D10: 0.65 | E10: 1
B11: GDD/Lösungskonzept | C11: 46063 | D11: 0.65 | E11: 1
B12: Teststrategie vorhanden | C12: 46063 | D12: 0.65 | E12: 1
B13: Freigabe für Umsetzung | C13: 46063 | D13: 0.65 | E13: 1
B14: Präsention beim Auftraggeber | C14: 46063 | D14: 0.65 | E14: 1
B15: Realisierung
B16: lauffähige Zwischenstand | C16: 46070 | D16: 1
B17: Testprotokolle | C17: 46070 | D17: 1
B18: Statusbericht | C18: 46070 | D18: 1
B19: Offene Risitken/Changes transparent Dokumentieren | C19: 46070 | D19: 1
B20: Einführung
B21: Abnahmeprotokoll | C21: 46077
B22: EXE‑Release | C22: 46077
B23: Schlussbericht | C23: 46077
B24: Lessons Learned | C24: 46077
B25: finale Bewertung | C25: 46077
B26: Dokumentation
B27: Sitzungsprotokoll Expertenbesuch | D27: 1 | E27: 1
B28: Arbeitsjournal | C28: 46056 | D28: 0 | E28: 0
B29: Arbeitsjournal | C29: 46058 | D29: 0 | E29: 0
B30: Arbeitsjournal | C30: 46063 | D30: 0 | E30: 0
B31: Arbeitsjournal | C31: 46065
B32: Arbeitsjournal | C32: 46070
B33: Arbeitsjournal | C33: 46072
B34: Arbeitsjournal | C34: 46077
B35: Reserven
B36: eingeplante Reserven
B37: Totale Arbeitszeit | D37: =SUM(D4:D8,D10:D14,D16:D19,D21:D25,D27:D34) -> 11.5

Sheet St.G
B2: Tätigkeit | C2: Datum | D2: SOLL Stunden | E2: IST Stunden
B3: Initialisierung
B4: PIA | C4: 46056 | D4: 0.65 | E4: 1
B5: Stakholderliste | C5: 46056 | D5: 0.65 | E5: 1
B6: Risikoliste vorhanden | C6: 46056 | D6: 0.65 | E6: 1
B7: Repo eingereicht | C7: 46056 | D7: 0.65 | E7: 1
B8: Freigabe durch Auftraggeber | C8: 46056 | D8: 0.65 | E8: 0.5
B9: Konzept
B10: PMP | C10: 46063 | D10: 0.65 | E10: 1
B11: GDD/Lösungskonzept | C11: 46063 | D11: 0.65 | E11: 1
B12: Teststrategie vorhanden | C12: 46063 | D12: 0.65 | E12: 1
B13: Freigabe für Umsetzung | C13: 46063 | D13: 0.65 | E13: 1
B14: Präsention beim Auftraggeber | C14: 46063 | D14: 0.65 | E14: 1
B15: Realisierung
B16: lauffähige Zwischenstand | C16: 46070 | D16: 1
B17: Testprotokolle | C17: 46070 | D17: 1
B18: Statusbericht | C18: 46070 | D18: 1
B19: Offene Risitken/Changes transparent Dokumentieren | C19: 46070 | D19: 1
B20: Einführung
B21: Abnahmeprotokoll | C21: 46077
B22: EXE‑Release | C22: 46077
B23: Schlussbericht | C23: 46077
B24: Lessons Learned | C24: 46077
B25: finale Bewertung | C25: 46077
B26: Dokumentation
B27: Sitzungsprotokoll Expertenbesuch
B28: Arbeitsjournal | C28: 46056 | D28: 0.5 | E28: 0.5
B29: Arbeitsjournal | C29: 46058 | D29: 0.5 | E29: 0.5
B30: Arbeitsjournal | C30: 46063 | D30: 0.5 | E30: 0.5
B31: Arbeitsjournal | C31: 46065
B32: Arbeitsjournal | C32: 46070
B33: Arbeitsjournal | C33: 46072
B34: Arbeitsjournal | C34: 46077
B35: Reserven
B36: eingeplante Reserven
B37: Totale Arbeitszeit | D37: =SUM(D4:D8,D10:D14,D16:D19,D21:D25,D27:D34) -> 12

Sheet Be.P
B2: Tätigkeit | C2: Datum | D2: SOLL Stunden | E2: IST Stunden
B3: Initialisierung
B4: PIA | C4: 46056 | D4: 0.65 | E4: 0
B5: Stakholderliste | C5: 46056 | D5: 0.65 | E5: 5
B6: Risikoliste vorhanden | C6: 46056 | D6: 0.65 | E6: 0
B7: Repo eingereicht | C7: 46056 | D7: 0.65 | E7: 0
B8: Freigabe durch Auftraggeber | C8: 46056 | D8: 0.65 | E8: 0.5
B9: Konzept
B10: PMP | C10: 46063 | D10: 0.65 | E10: 1
B11: GDD/Lösungskonzept | C11: 46063 | D11: 0.65 | E11: 0
B12: Teststrategie vorhanden | C12: 46063 | D12: 0.65 | E12: 0
B13: Freigabe für Umsetzung | C13: 46063 | D13: 0.65 | E13: 1
B14: Präsention beim Auftraggeber | C14: 46063 | D14: 0.65 | E14: 1
B15: Realisierung
B16: lauffähige Zwischenstand | C16: 46070 | D16: 1
B17: Testprotokolle | C17: 46070 | D17: 1
B18: Statusbericht | C18: 46070 | D18: 1
B19: Offene Risitken/Changes transparent Dokumentieren | C19: 46070 | D19: 1
B20: Einführung
B21: Abnahmeprotokoll | C21: 46077
B22: EXE‑Release | C22: 46077
B23: Schlussbericht | C23: 46077
B24: Lessons Learned | C24: 46077
B25: finale Bewertung | C25: 46077
B26: Dokumentation
B27: Sitzungsprotokoll Expertenbesuch
B28: Arbeitsjournal | C28: 46056 | D28: 0 | E28: 0
B29: Arbeitsjournal | C29: 46058 | D29: 0 | E29: 0
B30: Arbeitsjournal | C30: 46063 | D30: 0 | E30: 0
B31: Arbeitsjournal | C31: 46065
B32: Arbeitsjournal | C32: 46070
B33: Arbeitsjournal | C33: 46072
B34: Arbeitsjournal | C34: 46077
B35: Reserven
B36: eingeplante Reserven
B37: Totale Arbeitszeit | D37: =SUM(D4:D8,D10:D14,D16:D19,D21:D25,D27:D34,) -> 10.5

Sheet Su.S
B2: Tätigkeit | C2: Datum | D2: SOLL Stunden | E2: IST Stunden
B3: Initialisierung
B4: PIA | C4: 46056 | D4: 0.65 | E4: 1
B5: Stakholderliste | C5: 46056 | D5: 0.65 | E5: 0
B6: Risikoliste vorhanden | C6: 46056 | D6: 0.65 | E6: 0
B7: Repo eingereicht | C7: 46056 | D7: 0.65 | E7: 1
B8: Freigabe durch Auftraggeber | C8: 46056 | D8: 0.65 | E8: 0
B9: Konzept
B10: PMP | C10: 46063 | D10: 0.65 | E10: 0
B11: GDD/Lösungskonzept | C11: 46063 | D11: 0.65 | E11: 0
B12: Teststrategie vorhanden | C12: 46063 | D12: 0.65 | E12: 1
B13: Freigabe für Umsetzung | C13: 46063 | D13: 0.65 | E13: 1
B14: Präsention beim Auftraggeber | C14: 46063 | D14: 0.65 | E14: 1
B15: Realisierung
B16: lauffähige Zwischenstand | C16: 46070 | D16: 1
B17: Testprotokolle | C17: 46070 | D17: 1
B18: Statusbericht | C18: 46070 | D18: 1
B19: Offene Risitken/Changes transparent Dokumentieren | C19: 46070 | D19: 1
B20: Einführung
B21: Abnahmeprotokoll | C21: 46077
B22: EXE‑Release | C22: 46077
B23: Schlussbericht | C23: 46077
B24: Lessons Learned | C24: 46077
B25: finale Bewertung | C25: 46077
B26: Dokumentation
B27: Sitzungsprotokoll Expertenbesuch
B28: Arbeitsjournal | C28: 46056 | D28: 0 | E28: 0
B29: Arbeitsjournal | C29: 46058 | D29: 0 | E29: 0
B30: Arbeitsjournal | C30: 46063 | D30: 0 | E30: 0
B31: Arbeitsjournal | C31: 46065
B32: Arbeitsjournal | C32: 46070
B33: Arbeitsjournal | C33: 46072
B34: Arbeitsjournal | C34: 46077
B35: Reserven
B36: eingeplante Reserven
B37: Totale Arbeitszeit | D37: =SUM(D4:D8,D10:D14,D16:D19,D21:D25,D27:D34) -> 10.5
