Workbook
Name A_r_b_e_i_t_s_______P_l_a_n_u_n_g: [1]tabelle1!$B$1:$AG$74

Sheet Main
B1: Arbeitsplan Modul 306 - Gesamtübersicht (Min)
B2: Mitglieder: | D2: St.G | E2: Ch.G | F2: B.P | G2: S.S
B3: Aufgabe | C3: SOLL (Min) | D3: Tag 1 | E3: Tag 2 | F3: Tag 3 | G3: Tag 4 | H3: Tag 5 | I3: Tag 6 | J3: Tag 7 | K3: Total IST (Min)
B4: Datum | D4: 46084 | E4: 46091 | F4: 46098 | G4: 46099 | H4: 46100 | I4: 46102 | J4: 46105
B5: Initialisierung
B6: PIA | C6: 120 | D6: =SUM(St.G!D6,'Ch.G'!D6,B.P!D6,S.S!D6) -> 240 | E6: =SUM(St.G!E6,'Ch.G'!E6,B.P!E6,S.S!E6) -> 0 | F6: =SUM(St.G!F6,'Ch.G'!F6,B.P!F6,S.S!F6) -> 0 | G6: =SUM(St.G!G6,'Ch.G'!G6,B.P!G6,S.S!G6) -> 0 | H6: =SUM(St.G!H6,'Ch.G'!H6,B.P!H6,S.S!H6) -> 0 | I6: =SUM(St.G!I6,'Ch.G'!I6,B.P!I6,S.S!I6) -> 0 | J6: =SUM(St.G!J6,'Ch.G'!J6,B.P!J6,S.S!J6) -> 0 | K6: =SUM(D6:J6) -> 240
B7: Stakholderliste | C7: 30 | D7: =SUM(St.G!D7,'Ch.G'!D7,B.P!D7,S.S!D7) -> 20 | E7: =SUM(St.G!E7,'Ch.G'!E7,B.P!E7,S.S!E7) -> 0 | F7: =SUM(St.G!F7,'Ch.G'!F7,B.P!F7,S.S!F7) -> 0 | G7: =SUM(St.G!G7,'Ch.G'!G7,B.P!G7,S.S!G7) -> 0 | H7: =SUM(St.G!H7,'Ch.G'!H7,B.P!H7,S.S!H7) -> 0 | I7: =SUM(St.G!I7,'Ch.G'!I7,B.P!I7,S.S!I7) -> 0 | J7: =SUM(St.G!J7,'Ch.G'!J7,B.P!J7,S.S!J7) -> 0 | K7: =SUM(D7:J7) -> 20
B8: Risikoliste vorhanden | C8: 20 | D8: =SUM(St.G!D8,'Ch.G'!D8,B.P!D8,S.S!D8) -> 20 | E8: =SUM(St.G!E8,'Ch.G'!E8,B.P!E8,S.S!E8) -> 0 | F8: =SUM(St.G!F8,'Ch.G'!F8,B.P!F8,S.S!F8) -> 0 | G8: =SUM(St.G!G8,'Ch.G'!G8,B.P!G8,S.S!G8) -> 0 | H8: =SUM(St.G!H8,'Ch.G'!H8,B.P!H8,S.S!H8) -> 0 | I8: =SUM(St.G!I8,'Ch.G'!I8,B.P!I8,S.S!I8) -> 0 | J8: =SUM(St.G!J8,'Ch.G'!J8,B.P!J8,S.S!J8) -> 0 | K8: =SUM(D8:J8) -> 20
B9: Repo eingereicht | C9: 30 | D9: =SUM(St.G!D9,'Ch.G'!D9,B.P!D9,S.S!D9) -> 75 | E9: =SUM(St.G!E9,'Ch.G'!E9,B.P!E9,S.S!E9) -> 0 | F9: =SUM(St.G!F9,'Ch.G'!F9,B.P!F9,S.S!F9) -> 0 | G9: =SUM(St.G!G9,'Ch.G'!G9,B.P!G9,S.S!G9) -> 0 | H9: =SUM(St.G!H9,'Ch.G'!H9,B.P!H9,S.S!H9) -> 0 | I9: =SUM(St.G!I9,'Ch.G'!I9,B.P!I9,S.S!I9) -> 0 | J9: =SUM(St.G!J9,'Ch.G'!J9,B.P!J9,S.S!J9) -> 0 | K9: =SUM(D9:J9) -> 75
B10: Freigabe durch Auftraggeber | C10: 30 | D10: =SUM(St.G!D10,'Ch.G'!D10,B.P!D10,S.S!D10) -> 120 | E10: =SUM(St.G!E10,'Ch.G'!E10,B.P!E10,S.S!E10) -> 0 | F10: =SUM(St.G!F10,'Ch.G'!F10,B.P!F10,S.S!F10) -> 0 | G10: =SUM(St.G!G10,'Ch.G'!G10,B.P!G10,S.S!G10) -> 0 | H10: =SUM(St.G!H10,'Ch.G'!H10,B.P!H10,S.S!H10) -> 0 | I10: =SUM(St.G!I10,'Ch.G'!I10,B.P!I10,S.S!I10) -> 0 | J10: =SUM(St.G!J10,'Ch.G'!J10,B.P!J10,S.S!J10) -> 0 | K10: =SUM(D10:J10) -> 120
B11: Konzept
B12: PMP | C12: 24 | D12: =SUM(St.G!D12,'Ch.G'!D12,B.P!D12,S.S!D12) -> 0 | E12: =SUM(St.G!E12,'Ch.G'!E12,B.P!E12,S.S!E12) -> 0 | F12: =SUM(St.G!F12,'Ch.G'!F12,B.P!F12,S.S!F12) -> 0 | G12: =SUM(St.G!G12,'Ch.G'!G12,B.P!G12,S.S!G12) -> 0 | H12: =SUM(St.G!H12,'Ch.G'!H12,B.P!H12,S.S!H12) -> 0 | I12: =SUM(St.G!I12,'Ch.G'!I12,B.P!I12,S.S!I12) -> 0 | J12: =SUM(St.G!J12,'Ch.G'!J12,B.P!J12,S.S!J12) -> 0 | K12: =SUM(D12:J12) -> 0
B13: GDD/Lösungskonzept | C13: 36 | D13: =SUM(St.G!D13,'Ch.G'!D13,B.P!D13,S.S!D13) -> 0 | E13: =SUM(St.G!E13,'Ch.G'!E13,B.P!E13,S.S!E13) -> 0 | F13: =SUM(St.G!F13,'Ch.G'!F13,B.P!F13,S.S!F13) -> 0 | G13: =SUM(St.G!G13,'Ch.G'!G13,B.P!G13,S.S!G13) -> 0 | H13: =SUM(St.G!H13,'Ch.G'!H13,B.P!H13,S.S!H13) -> 0 | I13: =SUM(St.G!I13,'Ch.G'!I13,B.P!I13,S.S!I13) -> 0 | J13: =SUM(St.G!J13,'Ch.G'!J13,B.P!J13,S.S!J13) -> 0 | K13: =SUM(D13:J13) -> 0
B14: Teststrategie vorhanden | C14: 24 | D14: =SUM(St.G!D14,'Ch.G'!D14,B.P!D14,S.S!D14) -> 0 | E14: =SUM(St.G!E14,'Ch.G'!E14,B.P!E14,S.S!E14) -> 0 | F14: =SUM(St.G!F14,'Ch.G'!F14,B.P!F14,S.S!F14) -> 0 | G14: =SUM(St.G!G14,'Ch.G'!G14,B.P!G14,S.S!G14) -> 0 | H14: =SUM(St.G!H14,'Ch.G'!H14,B.P!H14,S.S!H14) -> 0 | I14: =SUM(St.G!I14,'Ch.G'!I14,B.P!I14,S.S!I14) -> 0 | J14: =SUM(St.G!J14,'Ch.G'!J14,B.P!J14,S.S!J14) -> 0 | K14: =SUM(D14:J14) -> 0
B15: Freigabe für Umsetzung | C15: 24 | D15: =SUM(St.G!D15,'Ch.G'!D15,B.P!D15,S.S!D15) -> 0 | E15: =SUM(St.G!E15,'Ch.G'!E15,B.P!E15,S.S!E15) -> 0 | F15: =SUM(St.G!F15,'Ch.G'!F15,B.P!F15,S.S!F15) -> 0 | G15: =SUM(St.G!G15,'Ch.G'!G15,B.P!G15,S.S!G15) -> 0 | H15: =SUM(St.G!H15,'Ch.G'!H15,B.P!H15,S.S!H15) -> 0 | I15: =SUM(St.G!I15,'Ch.G'!I15,B.P!I15,S.S!I15) -> 0 | J15: =SUM(St.G!J15,'Ch.G'!J15,B.P!J15,S.S!J15) -> 0 | K15: =SUM(D15:J15) -> 0
B16: Präsention beim Auftraggeber | C16: 24 | D16: =SUM(St.G!D16,'Ch.G'!D16,B.P!D16,S.S!D16) -> 0 | E16: =SUM(St.G!E16,'Ch.G'!E16,B.P!E16,S.S!E16) -> 0 | F16: =SUM(St.G!F16,'Ch.G'!F16,B.P!F16,S.S!F16) -> 0 | G16: =SUM(St.G!G16,'Ch.G'!G16,B.P!G16,S.S!G16) -> 0 | H16: =SUM(St.G!H16,'Ch.G'!H16,B.P!H16,S.S!H16) -> 0 | I16: =SUM(St.G!I16,'Ch.G'!I16,B.P!I16,S.S!I16) -> 0 | J16: =SUM(St.G!J16,'Ch.G'!J16,B.P!J16,S.S!J16) -> 0 | K16: =SUM(D16:J16) -> 0
B17: Realisierung
B18: lauffähige Zwischenstand | C18: 36 | D18: =SUM(St.G!D18,'Ch.G'!D18,B.P!D18,S.S!D18) -> 0 | E18: =SUM(St.G!E18,'Ch.G'!E18,B.P!E18,S.S!E18) -> 0 | F18: =SUM(St.G!F18,'Ch.G'!F18,B.P!F18,S.S!F18) -> 0 | G18: =SUM(St.G!G18,'Ch.G'!G18,B.P!G18,S.S!G18) -> 0 | H18: =SUM(St.G!H18,'Ch.G'!H18,B.P!H18,S.S!H18) -> 0 | I18: =SUM(St.G!I18,'Ch.G'!I18,B.P!I18,S.S!I18) -> 0 | J18: =SUM(St.G!J18,'Ch.G'!J18,B.P!J18,S.S!J18) -> 0 | K18: =SUM(D18:J18) -> 0
B19: Testprotokolle | C19: 36 | D19: =SUM(St.G!D19,'Ch.G'!D19,B.P!D19,S.S!D19) -> 0 | E19: =SUM(St.G!E19,'Ch.G'!E19,B.P!E19,S.S!E19) -> 0 | F19: =SUM(St.G!F19,'Ch.G'!F19,B.P!F19,S.S!F19) -> 0 | G19: =SUM(St.G!G19,'Ch.G'!G19,B.P!G19,S.S!G19) -> 0 | H19: =SUM(St.G!H19,'Ch.G'!H19,B.P!H19,S.S!H19) -> 0 | I19: =SUM(St.G!I19,'Ch.G'!I19,B.P!I19,S.S!I19) -> 0 | J19: =SUM(St.G!J19,'Ch.G'!J19,B.P!J19,S.S!J19) -> 0 | K19: =SUM(D19:J19) -> 0
B20: Statusbericht | C20: 72 | D20: =SUM(St.G!D20,'Ch.G'!D20,B.P!D20,S.S!D20) -> 0 | E20: =SUM(St.G!E20,'Ch.G'!E20,B.P!E20,S.S!E20) -> 0 | F20: =SUM(St.G!F20,'Ch.G'!F20,B.P!F20,S.S!F20) -> 0 | G20: =SUM(St.G!G20,'Ch.G'!G20,B.P!G20,S.S!G20) -> 0 | H20: =SUM(St.G!H20,'Ch.G'!H20,B.P!H20,S.S!H20) -> 0 | I20: =SUM(St.G!I20,'Ch.G'!I20,B.P!I20,S.S!I20) -> 0 | J20: =SUM(St.G!J20,'Ch.G'!J20,B.P!J20,S.S!J20) -> 0 | K20: =SUM(D20:J20) -> 0
B21: Offene Risitken/Changes transparent Dokumentieren | C21: 24 | D21: =SUM(St.G!D21,'Ch.G'!D21,B.P!D21,S.S!D21) -> 0 | E21: =SUM(St.G!E21,'Ch.G'!E21,B.P!E21,S.S!E21) -> 0 | F21: =SUM(St.G!F21,'Ch.G'!F21,B.P!F21,S.S!F21) -> 0 | G21: =SUM(St.G!G21,'Ch.G'!G21,B.P!G21,S.S!G21) -> 0 | H21: =SUM(St.G!H21,'Ch.G'!H21,B.P!H21,S.S!H21) -> 0 | I21: =SUM(St.G!I21,'Ch.G'!I21,B.P!I21,S.S!I21) -> 0 | J21: =SUM(St.G!J21,'Ch.G'!J21,B.P!J21,S.S!J21) -> 0 | K21: =SUM(D21:J21) -> 0
B22: Einführung
B23: Abnahmeprotokoll | C23: 24 | D23: =SUM(St.G!D23,'Ch.G'!D23,B.P!D23,S.S!D23) -> 0 | E23: =SUM(St.G!E23,'Ch.G'!E23,B.P!E23,S.S!E23) -> 0 | F23: =SUM(St.G!F23,'Ch.G'!F23,B.P!F23,S.S!F23) -> 0 | G23: =SUM(St.G!G23,'Ch.G'!G23,B.P!G23,S.S!G23) -> 0 | H23: =SUM(St.G!H23,'Ch.G'!H23,B.P!H23,S.S!H23) -> 0 | I23: =SUM(St.G!I23,'Ch.G'!I23,B.P!I23,S.S!I23) -> 0 | J23: =SUM(St.G!J23,'Ch.G'!J23,B.P!J23,S.S!J23) -> 0 | K23: =SUM(D23:J23) -> 0
B24: EXE‑Release | C24: 24 | D24: =SUM(St.G!D24,'Ch.G'!D24,B.P!D24,S.S!D24) -> 0 | E24: =SUM(St.G!E24,'Ch.G'!E24,B.P!E24,S.S!E24) -> 0 | F24: =SUM(St.G!F24,'Ch.G'!F24,B.P!F24,S.S!F24) -> 0 | G24: =SUM(St.G!G24,'Ch.G'!G24,B.P!G24,S.S!G24) -> 0 | H24: =SUM(St.G!H24,'Ch.G'!H24,B.P!H24,S.S!H24) -> 0 | I24: =SUM(St.G!I24,'Ch.G'!I24,B.P!I24,S.S!I24) -> 0 | J24: =SUM(St.G!J24,'Ch.G'!J24,B.P!J24,S.S!J24) -> 0 | K24: =SUM(D24:J24) -> 0
B25: Schlussbericht | C25: 24 | D25: =SUM(St.G!D25,'Ch.G'!D25,B.P!D25,S.S!D25) -> 0 | E25: =SUM(St.G!E25,'Ch.G'!E25,B.P!E25,S.S!E25) -> 0 | F25: =SUM(St.G!F25,'Ch.G'!F25,B.P!F25,S.S!F25) -> 0 | G25: =SUM(St.G!G25,'Ch.G'!G25,B.P!G25,S.S!G25) -> 0 | H25: =SUM(St.G!H25,'Ch.G'!H25,B.P!H25,S.S!H25) -> 0 | I25: =SUM(St.G!I25,'Ch.G'!I25,B.P!I25,S.S!I25) -> 0 | J25: =SUM(St.G!J25,'Ch.G'!J25,B.P!J25,S.S!J25) -> 0 | K25: =SUM(D25:J25) -> 0
B26: Lessons Learned | C26: 24 | D26: =SUM(St.G!D26,'Ch.G'!D26,B.P!D26,S.S!D26) -> 0 | E26: =SUM(St.G!E26,'Ch.G'!E26,B.P!E26,S.S!E26) -> 0 | F26: =SUM(St.G!F26,'Ch.G'!F26,B.P!F26,S.S!F26) -> 0 | G26: =SUM(St.G!G26,'Ch.G'!G26,B.P!G26,S.S!G26) -> 0 | H26: =SUM(St.G!H26,'Ch.G'!H26,B.P!H26,S.S!H26) -> 0 | I26: =SUM(St.G!I26,'Ch.G'!I26,B.P!I26,S.S!I26) -> 0 | J26: =SUM(St.G!J26,'Ch.G'!J26,B.P!J26,S.S!J26) -> 0 | K26: =SUM(D26:J26) -> 0
B27: finale Bewertung | C27: 60 | D27: =SUM(St.G!D27,'Ch.G'!D27,B.P!D27,S.S!D27) -> 0 | E27: =SUM(St.G!E27,'Ch.G'!E27,B.P!E27,S.S!E27) -> 0 | F27: =SUM(St.G!F27,'Ch.G'!F27,B.P!F27,S.S!F27) -> 0 | G27: =SUM(St.G!G27,'Ch.G'!G27,B.P!G27,S.S!G27) -> 0 | H27: =SUM(St.G!H27,'Ch.G'!H27,B.P!H27,S.S!H27) -> 0 | I27: =SUM(St.G!I27,'Ch.G'!I27,B.P!I27,S.S!I27) -> 0 | J27: =SUM(St.G!J27,'Ch.G'!J27,B.P!J27,S.S!J27) -> 0 | K27: =SUM(D27:J27) -> 0
B28: Dokumentation
B29: Sitzungsprotokoll Expertenbesuch | C29: 0 | D29: =SUM(St.G!D29,'Ch.G'!D29,B.P!D29,S.S!D29) -> 0 | E29: =SUM(St.G!E29,'Ch.G'!E29,B.P!E29,S.S!E29) -> 0 | F29: =SUM(St.G!F29,'Ch.G'!F29,B.P!F29,S.S!F29) -> 0 | G29: =SUM(St.G!G29,'Ch.G'!G29,B.P!G29,S.S!G29) -> 0 | H29: =SUM(St.G!H29,'Ch.G'!H29,B.P!H29,S.S!H29) -> 0 | I29: =SUM(St.G!I29,'Ch.G'!I29,B.P!I29,S.S!I29) -> 0 | J29: =SUM(St.G!J29,'Ch.G'!J29,B.P!J29,S.S!J29) -> 0 | K29: =SUM(D29:J29) -> 0
B30: Arbeitsjournal | C30: 180 | D30: =SUM(St.G!D30,'Ch.G'!D30,B.P!D30,S.S!D30) -> 0 | E30: =SUM(St.G!E30,'Ch.G'!E30,B.P!E30,S.S!E30) -> 0 | F30: =SUM(St.G!F30,'Ch.G'!F30,B.P!F30,S.S!F30) -> 0 | G30: =SUM(St.G!G30,'Ch.G'!G30,B.P!G30,S.S!G30) -> 0 | H30: =SUM(St.G!H30,'Ch.G'!H30,B.P!H30,S.S!H30) -> 0 | I30: =SUM(St.G!I30,'Ch.G'!I30,B.P!I30,S.S!I30) -> 0 | J30: =SUM(St.G!J30,'Ch.G'!J30,B.P!J30,S.S!J30) -> 0 | K30: =SUM(D30:J30) -> 0
B31: Termine
B32: Expertenbesuch 1 + 2 | C32: 60 | D32: =SUM(St.G!D32,'Ch.G'!D32,B.P!D32,S.S!D32) -> 0 | E32: =SUM(St.G!E32,'Ch.G'!E32,B.P!E32,S.S!E32) -> 0 | F32: =SUM(St.G!F32,'Ch.G'!F32,B.P!F32,S.S!F32) -> 0 | G32: =SUM(St.G!G32,'Ch.G'!G32,B.P!G32,S.S!G32) -> 0 | H32: =SUM(St.G!H32,'Ch.G'!H32,B.P!H32,S.S!H32) -> 0 | I32: =SUM(St.G!I32,'Ch.G'!I32,B.P!I32,S.S!I32) -> 0 | J32: =SUM(St.G!J32,'Ch.G'!J32,B.P!J32,S.S!J32) -> 0 | K32: =SUM(D32:J32) -> 0
B33: Reserven
B34: eingeplante Reserven | C34: 270 | D34: =SUM(St.G!D34,'Ch.G'!D34,B.P!D34,S.S!D34) -> 0 | E34: =SUM(St.G!E34,'Ch.G'!E34,B.P!E34,S.S!E34) -> 0 | F34: =SUM(St.G!F34,'Ch.G'!F34,B.P!F34,S.S!F34) -> 0 | G34: =SUM(St.G!G34,'Ch.G'!G34,B.P!G34,S.S!G34) -> 0 | H34: =SUM(St.G!H34,'Ch.G'!H34,B.P!H34,S.S!H34) -> 0 | I34: =SUM(St.G!I34,'Ch.G'!I34,B.P!I34,S.S!I34) -> 0 | J34: =SUM(St.G!J34,'Ch.G'!J34,B.P!J34,S.S!J34) -> 0 | K34: =SUM(D34:J34) -> 0
B36: Total pro Tag (Min) | C36: =SUM(C6,C7,C8,C9,C10,C12,C13,C14,C15,C16,C18,C19,C20,C21,C23,C24,C25,C26,C27,C29,C30,C32,C34) -> 1196 | D36: =SUM(D6,D7,D8,D9,D10,D12,D13,D14,D15,D16,D18,D19,D20,D21,D23,D24,D25,D26,D27,D29,D30,D32,D34) -> 475 | E36: =SUM(E6,E7,E8,E9,E10,E12,E13,E14,E15,E16,E18,E19,E20,E21,E23,E24,E25,E26,E27,E29,E30,E32,E34) -> 0 | F36: =SUM(F6,F7,F8,F9,F10,F12,F13,F14,F15,F16,F18,F19,F20,F21,F23,F24,F25,F26,F27,F29,F30,F32,F34) -> 0 | G36: =SUM(G6,G7,G8,G9,G10,G12,G13,G14,G15,G16,G18,G19,G20,G21,G23,G24,G25,G26,G27,G29,G30,G32,G34) -> 0 | H36: =SUM(H6,H7,H8,H9,H10,H12,H13,H14,H15,H16,H18,H19,H20,H21,H23,H24,H25,H26,H27,H29,H30,H32,H34) -> 0 | I36: =SUM(I6,I7,I8,I9,I10,I12,I13,I14,I15,I16,I18,I19,I20,I21,I23,I24,I25,I26,I27,I29,I30,I32,I34) -> 0 | J36: =SUM(J6,J7,J8,J9,J10,J12,J13,J14,J15,J16,J18,J19,J20,J21,J23,J24,J25,J26,J27,J29,J30,J32,J34) -> 0 | K36: =SUM(D36:J36) -> 475
B37: Abweichung (SOLL - IST) | K37: =C36-K36 -> 721
B39: Zusammenfassung pro Mitglied (Min)
B40: Mitglied | D40: Tag 1 | E40: Tag 2 | F40: Tag 3 | G40: Tag 4 | H40: Tag 5 | I40: Tag 6 | J40: Tag 7 | K40: Total (Min)
B41: St.G | D41: =St.G!D36 -> 115 | E41: =St.G!E36 -> 0 | F41: =St.G!F36 -> 0 | G41: =St.G!G36 -> 0 | H41: =St.G!H36 -> 0 | I41: =St.G!I36 -> 0 | J41: =St.G!J36 -> 0 | K41: =SUM(D41:J41) -> 115
B42: Ch.G | D42: ='Ch.G'!D36 -> 130 | E42: ='Ch.G'!E36 -> 0 | F42: ='Ch.G'!F36 -> 0 | G42: ='Ch.G'!G36 -> 0 | H42: ='Ch.G'!H36 -> 0 | I42: ='Ch.G'!I36 -> 0 | J42: ='Ch.G'!J36 -> 0 | K42: =SUM(D42:J42) -> 130
...

Sheet St.G
B1: Zeiterfassung - St.G
B3: Aufgabe | C3: SOLL (Min) | D3: Tag 1 | E3: Tag 2 | F3: Tag 3 | G3: Tag 4 | H3: Tag 5 | I3: Tag 6 | J3: Tag 7 | K3: Total (Min)
B4: Datum | D4: 46084 | E4: 46091 | F4: 46098 | G4: 46099 | H4: 46100 | I4: 46102 | J4: 46105
B5: Initialisierung
B6: PIA | C6: 60 | D6: 60 | K6: =SUM(D6:J6) -> 60
B7: Stakholderliste | C7: 5 | D7: 5 | K7: =SUM(D7:J7) -> 5
B8: Risikoliste vorhanden | C8: 5 | D8: 5 | K8: =SUM(D8:J8) -> 5
B9: Repo eingereicht | C9: 15 | D9: 15 | K9: =SUM(D9:J9) -> 15
B10: Freigabe durch Auftraggeber | C10: 30 | D10: 30 | K10: =SUM(D10:J10) -> 30
B11: Konzept
B12: PMP | C12: 24 | K12: =SUM(D12:J12) -> 0
B13: GDD/Lösungskonzept | C13: 36 | K13: =SUM(D13:J13) -> 0
B14: Teststrategie vorhanden | C14: 24 | K14: =SUM(D14:J14) -> 0
B15: Freigabe für Umsetzung | C15: 24 | K15: =SUM(D15:J15) -> 0
B16: Präsention beim Auftraggeber | C16: 24 | K16: =SUM(D16:J16) -> 0
B17: Realisierung
B18: lauffähige Zwischenstand | C18: 36 | K18: =SUM(D18:J18) -> 0
B19: Testprotokolle | C19: 36 | K19: =SUM(D19:J19) -> 0
B20: Statusbericht | C20: 72 | K20: =SUM(D20:J20) -> 0
B21: Offene Risitken/Changes transparent Dokumentieren | C21: 24 | K21: =SUM(D21:J21) -> 0
B22: Einführung
B23: Abnahmeprotokoll | C23: 24 | K23: =SUM(D23:J23) -> 0
B24: EXE‑Release | C24: 24 | K24: =SUM(D24:J24) -> 0
B25: Schlussbericht | C25: 24 | K25: =SUM(D25:J25) -> 0
B26: Lessons Learned | C26: 24 | K26: =SUM(D26:J26) -> 0
B27: finale Bewertung | C27: 60 | K27: =SUM(D27:J27) -> 0
B28: Dokumentation
B29: Sitzungsprotokoll Expertenbesuch | C29: 0 | K29: =SUM(D29:J29) -> 0
B30: Arbeitsjournal | C30: 180 | K30: =SUM(D30:J30) -> 0
B31: Termine
B32: Expertenbesuch 1 + 2 | C32: 60 | K32: =SUM(D32:J32) -> 0
B33: Reserven
B34: eingeplante Reserven | C34: 270 | K34: =SUM(D34:J34) -> 0
B36: Total pro Tag (Min) | C36: =SUM(C6,C7,C8,C9,C10,C12,C13,C14,C15,C16,C18,C19,C20,C21,C23,C24,C25,C26,C27,C29,C30,C32,C34) -> 1081 | D36: =SUM(D6,D7,D8,D9,D10,D12,D13,D14,D15,D16,D18,D19,D20,D21,D23,D24,D25,D26,D27,D29,D30,D32,D34) -> 115 | E36: =SUM(E6,E7,E8,E9,E10,E12,E13,E14,E15,E16,E18,E19,E20,E21,E23,E24,E25,E26,E27,E29,E30,E32,E34) -> 0 | F36: =SUM(F6,F7,F8,F9,F10,F12,F13,F14,F15,F16,F18,F19,F20,F21,F23,F24,F25,F26,F27,F29,F30,F32,F34) -> 0 | G36: =SUM(G6,G7,G8,G9,G10,G12,G13,G14,G15,G16,G18,G19,G20,G21,G23,G24,G25,G26,G27,G29,G30,G32,G34) -> 0 | H36: =SUM(H6,H7,H8,H9,H10,H12,H13,H14,H15,H16,H18,H19,H20,H21,H23,H24,H25,H26,H27,H29,H30,H32,H34) -> 0 | I36: =SUM(I6,I7,I8,I9,I10,I12,I13,I14,I15,I16,I18,I19,I20,I21,I23,I24,I25,I26,I27,I29,I30,I32,I34) -> 0 | J36: =SUM(J6,J7,J8,J9,J10,J12,J13,J14,J15,J16,J18,J19,J20,J21,J23,J24,J25,J26,J27,J29,J30,J32,J34) -> 0 | K36: =SUM(D36:J36) -> 115

Sheet Ch.G
B1: Zeiterfassung - Ch.G
B3: Aufgabe | C3: SOLL (Min) | D3: Tag 1 | E3: Tag 2 | F3: Tag 3 | G3: Tag 4 | H3: Tag 5 | I3: Tag 6 | J3: Tag 7 | K3: Total (Min)
B4: Datum | D4: 46084 | E4: 46091 | F4: 46098 | G4: 46099 | H4: 46100 | I4: 46102 | J4: 46105
B5: Initialisierung
B6: PIA | C6: 60 | D6: 60 | K6: =SUM(D6:J6) -> 60
B7: Stakholderliste | C7: 5 | D7: 5 | K7: =SUM(D7:J7) -> 5
B8: Risikoliste vorhanden | C8: 5 | D8: 5 | K8: =SUM(D8:J8) -> 5
B9: Repo eingereicht | C9: 30 | D9: 30 | K9: =SUM(D9:J9) -> 30
B10: Freigabe durch Auftraggeber | C10: 30 | D10: 30 | K10: =SUM(D10:J10) -> 30
B11: Konzept
B12: PMP | C12: 24 | K12: =SUM(D12:J12) -> 0
B13: GDD/Lösungskonzept | C13: 36 | K13: =SUM(D13:J13) -> 0
B14: Teststrategie vorhanden | C14: 24 | K14: =SUM(D14:J14) -> 0
B15: Freigabe für Umsetzung | C15: 24 | K15: =SUM(D15:J15) -> 0
B16: Präsention beim Auftraggeber | C16: 24 | K16: =SUM(D16:J16) -> 0
B17: Realisierung
B18: lauffähige Zwischenstand | C18: 36 | K18: =SUM(D18:J18) -> 0
B19: Testprotokolle | C19: 36 | K19: =SUM(D19:J19) -> 0
B20: Statusbericht | C20: 72 | K20: =SUM(D20:J20) -> 0
B21: Offene Risitken/Changes transparent Dokumentieren | C21: 24 | K21: =SUM(D21:J21) -> 0
B22: Einführung
B23: Abnahmeprotokoll | C23: 24 | K23: =SUM(D23:J23) -> 0
B24: EXE‑Release | C24: 24 | K24: =SUM(D24:J24) -> 0
B25: Schlussbericht | C25: 24 | K25: =SUM(D25:J25) -> 0
B26: Lessons Learned | C26: 24 | K26: =SUM(D26:J26) -> 0
B27: finale Bewertung | C27: 60 | K27: =SUM(D27:J27) -> 0
B28: Dokumentation
B29: Sitzungsprotokoll Expertenbesuch | C29: 0 | K29: =SUM(D29:J29) -> 0
B30: Arbeitsjournal | C30: 180 | K30: =SUM(D30:J30) -> 0
B31: Termine
B32: Expertenbesuch 1 + 2 | C32: 60 | K32: =SUM(D32:J32) -> 0
B33: Reserven
B34: eingeplante Reserven | C34: 270 | K34: =SUM(D34:J34) -> 0
B36: Total pro Tag (Min) | C36: =SUM(C6,C7,C8,C9,C10,C12,C13,C14,C15,C16,C18,C19,C20,C21,C23,C24,C25,C26,C27,C29,C30,C32,C34) -> 1096 | D36: =SUM(D6,D7,D8,D9,D10,D12,D13,D14,D15,D16,D18,D19,D20,D21,D23,D24,D25,D26,D27,D29,D30,D32,D34) -> 130 | E36: =SUM(E6,E7,E8,E9,E10,E12,E13,E14,E15,E16,E18,E19,E20,E21,E23,E24,E25,E26,E27,E29,E30,E32,E34) -> 0 | F36: =SUM(F6,F7,F8,F9,F10,F12,F13,F14,F15,F16,F18,F19,F20,F21,F23,F24,F25,F26,F27,F29,F30,F32,F34) -> 0 | G36: =SUM(G6,G7,G8,G9,G10,G12,G13,G14,G15,G16,G18,G19,G20,G21,G23,G24,G25,G26,G27,G29,G30,G32,G34) -> 0 | H36: =SUM(H6,H7,H8,H9,H10,H12,H13,H14,H15,H16,H18,H19,H20,H21,H23,H24,H25,H26,H27,H29,H30,H32,H34) -> 0 | I36: =SUM(I6,I7,I8,I9,I10,I12,I13,I14,I15,I16,I18,I19,I20,I21,I23,I24,I25,I26,I27,I29,I30,I32,I34) -> 0 | J36: =SUM(J6,J7,J8,J9,J10,J12,J13,J14,J15,J16,J18,J19,J20,J21,J23,J24,J25,J26,J27,J29,J30,J32,J34) -> 0 | K36: =SUM(D36:J36) -> 130

Sheet B.P
B1: Zeiterfassung - B.P
B3: Aufgabe | C3: SOLL (Min) | D3: Tag 1 | E3: Tag 2 | F3: Tag 3 | G3: Tag 4 | H3: Tag 5 | I3: Tag 6 | J3: Tag 7 | K3: Total (Min)
B4: Datum | D4: 46084 | E4: 46091 | F4: 46098 | G4: 46099 | H4: 46100 | I4: 46102 | J4: 46105
B5: Initialisierung
B6: PIA | C6: 60 | D6: 60 | K6: =SUM(D6:J6) -> 60
B7: Stakholderliste | C7: 5 | D7: 5 | K7: =SUM(D7:J7) -> 5
B8: Risikoliste vorhanden | C8: 5 | D8: 5 | K8: =SUM(D8:J8) -> 5
B9: Repo eingereicht | C9: 15 | D9: 15 | K9: =SUM(D9:J9) -> 15
B10: Freigabe durch Auftraggeber | C10: 30 | D10: 30 | K10: =SUM(D10:J10) -> 30
B11: Konzept
B12: PMP | C12: 24 | K12: =SUM(D12:J12) -> 0
B13: GDD/Lösungskonzept | C13: 36 | K13: =SUM(D13:J13) -> 0
B14: Teststrategie vorhanden | C14: 24 | K14: =SUM(D14:J14) -> 0
B15: Freigabe für Umsetzung | C15: 24 | K15: =SUM(D15:J15) -> 0
B16: Präsention beim Auftraggeber | C16: 24 | K16: =SUM(D16:J16) -> 0
B17: Realisierung
B18: lauffähige Zwischenstand | C18: 36 | K18: =SUM(D18:J18) -> 0
B19: Testprotokolle | C19: 36 | K19: =SUM(D19:J19) -> 0
B20: Statusbericht | C20: 72 | K20: =SUM(D20:J20) -> 0
B21: Offene Risitken/Changes transparent Dokumentieren | C21: 24 | K21: =SUM(D21:J21) -> 0
B22: Einführung
B23: Abnahmeprotokoll | C23: 24 | K23: =SUM(D23:J23) -> 0
B24: EXE‑Release | C24: 24 | K24: =SUM(D24:J24) -> 0
B25: Schlussbericht | C25: 24 | K25: =SUM(D25:J25) -> 0
B26: Lessons Learned | C26: 24 | K26: =SUM(D26:J26) -> 0
B27: finale Bewertung | C27: 60 | K27: =SUM(D27:J27) -> 0
B28: Dokumentation
B29: Sitzungsprotokoll Expertenbesuch | C29: 0 | K29: =SUM(D29:J29) -> 0
B30: Arbeitsjournal | C30: 180 | K30: =SUM(D30:J30) -> 0
B31: Termine
B32: Expertenbesuch 1 + 2 | C32: 60 | K32: =SUM(D32:J32) -> 0
B33: Reserven
B34: eingeplante Reserven | C34: 270 | K34: =SUM(D34:J34) -> 0
B36: Total pro Tag (Min) | C36: =SUM(C6,C7,C8,C9,C10,C12,C13,C14,C15,C16,C18,C19,C20,C21,C23,C24,C25,C26,C27,C29,C30,C32,C34) -> 1081 | D36: =SUM(D6,D7,D8,D9,D10,D12,D13,D14,D15,D16,D18,D19,D20,D21,D23,D24,D25,D26,D27,D29,D30,D32,D34) -> 115 | E36: =SUM(E6,E7,E8,E9,E10,E12,E13,E14,E15,E16,E18,E19,E20,E21,E23,E24,E25,E26,E27,E29,E30,E32,E34) -> 0 | F36: =SUM(F6,F7,F8,F9,F10,F12,F13,F14,F15,F16,F18,F19,F20,F21,F23,F24,F25,F26,F27,F29,F30,F32,F34) -> 0 | G36: =SUM(G6,G7,G8,G9,G10,G12,G13,G14,G15,G16,G18,G19,G20,G21,G23,G24,G25,G26,G27,G29,G30,G32,G34) -> 0 | H36: =SUM(H6,H7,H8,H9,H10,H12,H13,H14,H15,H16,H18,H19,H20,H21,H23,H24,H25,H26,H27,H29,H30,H32,H34) -> 0 | I36: =SUM(I6,I7,I8,I9,I10,I12,I13,I14,I15,I16,I18,I19,I20,I21,I23,I24,I25,I26,I27,I29,I30,I32,I34) -> 0 | J36: =SUM(J6,J7,J8,J9,J10,J12,J13,J14,J15,J16,J18,J19,J20,J21,J23,J24,J25,J26,J27,J29,J30,J32,J34) -> 0 | K36: =SUM(D36:J36) -> 115

Sheet S.S
B1: Zeiterfassung - S.S
B3: Aufgabe | C3: SOLL (Min) | D3: Tag 1 | E3: Tag 2 | F3: Tag 3 | G3: Tag 4 | H3: Tag 5 | I3: Tag 6 | J3: Tag 7 | K3: Total (Min)
B4: Datum | D4: 46084 | E4: 46091 | F4: 46098 | G4: 46099 | H4: 46100 | I4: 46102 | J4: 46105
B5: Initialisierung
B6: PIA | C6: 60 | D6: 60 | K6: =SUM(D6:J6) -> 60
B7: Stakholderliste | C7: 5 | D7: 5 | K7: =SUM(D7:J7) -> 5
B8: Risikoliste vorhanden | C8: 5 | D8: 5 | K8: =SUM(D8:J8) -> 5
B9: Repo eingereicht | C9: 15 | D9: 15 | K9: =SUM(D9:J9) -> 15
B10: Freigabe durch Auftraggeber | C10: 30 | D10: 30 | K10: =SUM(D10:J10) -> 30
B11: Konzept
B12: PMP | C12: 24 | K12: =SUM(D12:J12) -> 0
B13: GDD/Lösungskonzept | C13: 36 | K13: =SUM(D13:J13) -> 0
B14: Teststrategie vorhanden | C14: 24 | K14: =SUM(D14:J14) -> 0
B15: Freigabe für Umsetzung | C15: 24 | K15: =SUM(D15:J15) -> 0
B16: Präsention beim Auftraggeber | C16: 24 | K16: =SUM(D16:J16) -> 0
B17: Realisierung
B18: lauffähige Zwischenstand | C18: 36 | K18: =SUM(D18:J18) -> 0
B19: Testprotokolle | C19: 36 | K19: =SUM(D19:J19) -> 0
B20: Statusbericht | C20: 72 | K20: =SUM(D20:J20) -> 0
B21: Offene Risitken/Changes transparent Dokumentieren | C21: 24 | K21: =SUM(D21:J21) -> 0
B22: Einführung
B23: Abnahmeprotokoll | C23: 24 | K23: =SUM(D23:J23) -> 0
B24: EXE‑Release | C24: 24 | K24: =SUM(D24:J24) -> 0
B25: Schlussbericht | C25: 24 | K25: =SUM(D25:J25) -> 0
B26: Lessons Learned | C26: 24 | K26: =SUM(D26:J26) -> 0
B27: finale Bewertung | C27: 60 | K27: =SUM(D27:J27) -> 0
B28: Dokumentation
B29: Sitzungsprotokoll Expertenbesuch | C29: 0 | K29: =SUM(D29:J29) -> 0
B30: Arbeitsjournal | C30: 180 | K30: =SUM(D30:J30) -> 0
B31: Termine
B32: Expertenbesuch 1 + 2 | C32: 60 | K32: =SUM(D32:J32) -> 0
B33: Reserven
B34: eingeplante Reserven | C34: 270 | K34: =SUM(D34:J34) -> 0
B36: Total pro Tag (Min) | C36: =SUM(C6,C7,C8,C9,C10,C12,C13,C14,C15,C16,C18,C19,C20,C21,C23,C24,C25,C26,C27,C29,C30,C32,C34) -> 1081 | D36: =SUM(D6,D7,D8,D9,D10,D12,D13,D14,D15,D16,D18,D19,D20,D21,D23,D24,D25,D26,D27,D29,D30,D32,D34) -> 115 | E36: =SUM(E6,E7,E8,E9,E10,E12,E13,E14,E15,E16,E18,E19,E20,E21,E23,E24,E25,E26,E27,E29,E30,E32,E34) -> 0 | F36: =SUM(F6,F7,F8,F9,F10,F12,F13,F14,F15,F16,F18,F19,F20,F21,F23,F24,F25,F26,F27,F29,F30,F32,F34) -> 0 | G36: =SUM(G6,G7,G8,G9,G10,G12,G13,G14,G15,G16,G18,G19,G20,G21,G23,G24,G25,G26,G27,G29,G30,G32,G34) -> 0 | H36: =SUM(H6,H7,H8,H9,H10,H12,H13,H14,H15,H16,H18,H19,H20,H21,H23,H24,H25,H26,H27,H29,H30,H32,H34) -> 0 | I36: =SUM(I6,I7,I8,I9,I10,I12,I13,I14,I15,I16,I18,I19,I20,I21,I23,I24,I25,I26,I27,I29,I30,I32,I34) -> 0 | J36: =SUM(J6,J7,J8,J9,J10,J12,J13,J14,J15,J16,J18,J19,J20,J21,J23,J24,J25,J26,J27,J29,J30,J32,J34) -> 0 | K36: =SUM(D36:J36) -> 115
